<?xml version="1.0"?>
<robot xmlns:xacro="http://www.ros.org/wiki/xacro" name="car_bot">

    <!-- Robot Material Colors -->
    <material name="blue">
        <color rgba="0.2 0.2 1 1"/>
    </material>

    <material name="black">
        <color rgba="0 0 0 1"/>
    </material>

    <material name="white">
        <color rgba="1 1 1 1"/>
    </material>

    <!-- Base Link (Chassis) -->
    <link name="base_link">
    </link>

    <!-- Chassis Link -->
    <joint name="chassis_joint" type="fixed">
        <parent link="base_link"/>
        <child link="chassis"/>
        <origin xyz="0 0 0.1"/>
    </joint>

    <link name="chassis">
        <visual>
            <origin xyz="0 0 0.05" rpy="0 0 0"/>
            <geometry>
                <box size="0.6 0.3 0.1"/>
            </geometry>
            <material name="blue"/>
        </visual>
        <collision>
            <origin xyz="0 0 0.05" rpy="0 0 0"/>
            <geometry>
                <box size="0.6 0.3 0.1"/>
            </geometry>
        </collision>
        <inertial>
            <origin xyz="0 0 0.05" rpy="0 0 0"/>
            <mass value="2.0"/>
            <inertia ixx="0.0166" ixy="0.0" ixz="0.0" iyy="0.0616" iyz="0.0" izz="0.075"/>
        </inertial>
    </link>

    <!-- LIDAR -->
    <joint name="laser_joint" type="fixed">
        <parent link="chassis"/>
        <child link="laser_frame"/>
        <origin xyz="0.1 0 0.1" rpy="0 0 0"/>
    </joint>

    <link name="laser_frame">
        <visual>
            <geometry>
                <cylinder radius="0.05" length="0.04"/>
            </geometry>
            <material name="red">
                <color rgba="1 0 0 1"/>
            </material>
        </visual>
        <collision>
            <geometry>
                <cylinder radius="0.05" length="0.04"/>
            </geometry>
        </collision>
        <inertial>
            <mass value="0.1"/>
            <inertia ixx="0.001" ixy="0" ixz="0" iyy="0.001" iyz="0" izz="0.001"/>
        </inertial>
    </link>

    <gazebo reference="laser_frame">
        <sensor name="lidar" type="gpu_lidar">
            <pose>0 0 0 0 0 0</pose>
            <always_on>true</always_on>
            <visualize>true</visualize>
            <update_rate>10</update_rate>
            <topic>scan</topic>
            <frame_id>laser_frame</frame_id>
            <ray>
                <scan>
                    <horizontal>
                        <samples>360</samples>
                        <resolution>1</resolution>
                        <min_angle>-3.14</min_angle>
                        <max_angle>3.14</max_angle>
                    </horizontal>
                </scan>
                <range>
                    <min>0.3</min>
                    <max>12</max>
                </range>
            </ray>
        </sensor>
    </gazebo>

    <!-- FRONT WHEELS (Fixed Casters) -->
    <xacro:macro name="front_wheel" params="prefix x_reflect y_reflect">
        <link name="${prefix}_wheel">
            <visual>
                <origin xyz="0 0 0" rpy="${pi/2} 0 0"/>
                <geometry>
                    <cylinder radius="0.05" length="0.04"/>
                </geometry>
                <material name="black"/>
            </visual>
            <collision>
                <origin xyz="0 0 0" rpy="${pi/2} 0 0"/>
                <geometry>
                    <cylinder radius="0.05" length="0.04"/>
                </geometry>
            </collision>
            <inertial>
                <origin xyz="0 0 0" rpy="0 0 0"/>
                <mass value="0.5"/>
                <inertia ixx="0.00037" ixy="0.0" ixz="0.0" iyy="0.00037" iyz="0.0" izz="0.000625"/>
            </inertial>
        </link>

        <joint name="${prefix}_wheel_joint" type="fixed">
            <parent link="base_link"/>
            <child link="${prefix}_wheel"/>
            <origin xyz="${x_reflect*0.2} ${y_reflect*0.175} 0.05" rpy="0 0 0"/>
        </joint>

        <gazebo reference="${prefix}_wheel">
            <mu1>0.001</mu1>
            <mu2>0.001</mu2>
        </gazebo>
    </xacro:macro>

    <!-- REAR WHEELS (Driven) -->
    <xacro:macro name="rear_wheel" params="prefix x_reflect y_reflect">
        <link name="${prefix}_wheel">
            <visual>
                <origin xyz="0 0 0" rpy="${pi/2} 0 0"/>
                <geometry>
                    <cylinder radius="0.05" length="0.04"/>
                </geometry>
                <material name="black"/>
            </visual>
            <collision>
                <origin xyz="0 0 0" rpy="${pi/2} 0 0"/>
                <geometry>
                    <cylinder radius="0.05" length="0.04"/>
                </geometry>
            </collision>
            <inertial>
                <origin xyz="0 0 0" rpy="0 0 0"/>
                <mass value="0.5"/>
                <inertia ixx="0.00037" ixy="0.0" ixz="0.0" iyy="0.00037" iyz="0.0" izz="0.000625"/>
            </inertial>
        </link>

        <joint name="${prefix}_wheel_joint" type="continuous">
            <parent link="base_link"/>
            <child link="${prefix}_wheel"/>
            <origin xyz="${x_reflect*0.2} ${y_reflect*0.175} 0.05" rpy="0 0 0"/>
            <axis xyz="0 1 0"/>
        </joint>

        <gazebo reference="${prefix}_wheel">
            <mu1>2.0</mu1>
            <mu2>2.0</mu2>
        </gazebo>
    </xacro:macro>

    <!-- Create Wheels -->
    <xacro:front_wheel prefix="front_left" x_reflect="1" y_reflect="1"/>
    <xacro:front_wheel prefix="front_right" x_reflect="1" y_reflect="-1"/>
    <xacro:rear_wheel prefix="rear_left" x_reflect="-1" y_reflect="1"/>
    <xacro:rear_wheel prefix="rear_right" x_reflect="-1" y_reflect="-1"/>

    <!-- Gazebo Plugin for Diff Drive (Rear Wheels Only) -->
    <gazebo>
        <plugin filename="gz-sim-diff-drive-system" name="gz::sim::systems::DiffDrive">
            <left_joint>rear_left_wheel_joint</left_joint>
            <right_joint>rear_right_wheel_joint</right_joint>
            <wheel_separation>0.35</wheel_separation>
            <wheel_radius>0.05</wheel_radius>
            <odom_publish_frequency>50</odom_publish_frequency>
            <topic>cmd_vel</topic>
            <odom_topic>odom</odom_topic>
            <frame_id>odom</frame_id>
            <child_frame_id>base_link</child_frame_id>
            <covariance_x>0.0001</covariance_x>
            <covariance_y>0.0001</covariance_y>
            <covariance_yaw>0.01</covariance_yaw>
        </plugin>




        
        <!-- Joint State Publisher for Wheel TFs -->
        <plugin filename="gz-sim-joint-state-publisher-system" name="gz::sim::systems::JointStatePublisher">
            <topic>joint_states</topic>
            <joint_name>rear_left_wheel_joint</joint_name>
            <joint_name>rear_right_wheel_joint</joint_name>
        </plugin>
    </gazebo>

</robot>
